Workbook
Name Bild: Allgemein!$L$2
Name DAIKIN: Heizungsauswahl[DAIKIN]
Name DAIKIN: Heizungsauswahl[DAIKIN]
Name DAIKIN: Heizungsauswahl[DAIKIN]
Name Heizungshersteller: Heizungsauswahl[Hersteller]
Name Heizungshersteller: Heizungsauswahl[Hersteller]
Name Heizungshersteller: Heizungsauswahl[Hersteller]
Name LG: Heizungsauswahl[LG]
Name LG: Heizungsauswahl[LG]
Name LG: Heizungsauswahl[LG]
Name r_Adresse: Datenaustausch!$D$5:$D$8
Name r_Angaben: Datenaustausch!$C$10:$E$15
Name r_Ausgaben: Datenaustausch!$BV$13:$BW$17
Name r_BEGEM: Datenaustausch!$BI$30:$BM$38
Name r_BEGWG: Datenaustausch!$BI$41:$BM$43
Name r_CO2Flugnach: Datenaustausch!$K$26
Name r_Co2Flugvor: Datenaustausch!$K$25
Name r_CO2Nach: Datenaustausch!$E$26
Name r_CO2Vor: Datenaustausch!$E$25
Name r_CO2Weltnach: Datenaustausch!$J$26
Name r_CO2Weltvor: Datenaustausch!$J$25
Name r_Dach: Datenaustausch!$BR$23:$BS$23
Name r_Effizienshaus: Datenaustausch!$J$32
Name r_EffizienzhausVAR1: Datenaustausch!$AJ$57
Name r_EffizienzhausVAR2: Datenaustausch!$AJ$79
Name r_EffizienzhausVAR3: Datenaustausch!$AJ$98
Name r_Einnahmen: Datenaustausch!$BR$13:$BS$17
Name r_EinsparungenEMPF: Datenaustausch!$AQ$13:$AR$14
Name r_EinsparungenVar1: Datenaustausch!$AC$13:$AD$14
Name r_EinsparungenVar2: Datenaustausch!$AG$13:$AH$14
Name r_EinsparungenVar3: Datenaustausch!$AL$13:$AM$14
Name r_EinsparungTabelleEMPF: Datenaustausch!$AQ$31:$AR$31
Name r_EinsparungTabelleVAR1: Datenaustausch!$AC$31:$AD$31
Name r_EinsparungTabelleVAR2: Datenaustausch!$AG$31:$AH$31
Name r_EinsparungTabelleVAR3: Datenaustausch!$AL$31:$AM$31
Name r_EndenergiebedarfText: Datenaustausch!$BV$6:$BX$8
Name r_Energieeffizienzklasse: Datenaustausch!$AS$85
Name r_EnergielabelVar1: Datenaustausch!$AG$57
Name r_EnergielabelVar2: Datenaustausch!$AG$79
Name r_EnergielabelVar3: Datenaustausch!$AG$98
Name r_Ersparniss: Datenaustausch!$J$31
Name r_Fassade: Datenaustausch!$BR$24:$BS$24
Name r_Fenster: Datenaustausch!$BR$25:$BS$25
Name r_HeizundStromenergie: Datenaustausch!$C$17:$E$22
Name r_HeizundStromkosten: Datenaustausch!$G$17:$I$22
Name r_Heizung: Datenaustausch!$BR$29:$BS$29
Name r_Keller: Datenaustausch!$BR$27:$BS$27
Name r_KostenbilanzEMPF: Datenaustausch!$AQ$46:$AR$46
Name r_KostenbilanzUMSETZ: Datenaustausch!$AQ$33:$AR$33
Name r_KostenbilanzVAR1: Datenaustausch!$AC$33:$AD$33
Name r_KostenbilanzVAR2: Datenaustausch!$AG$33:$AH$33
Name r_KostenbilanzVAR3: Datenaustausch!$AL$33:$AM$33
Name r_KostenEMPF: Datenaustausch!$AQ$17:$AR$20
Name r_KostenTabelleEMPF: Datenaustausch!$AQ$32:$AR$32
Name r_KostenTabelleVAR1: Datenaustausch!$AC$32:$AD$32
Name r_KostenTabelleVAR2: Datenaustausch!$AG$32:$AH$32
Name r_KostenTabelleVAR3: Datenaustausch!$AL$32:$AM$32
Name r_KostenVAR1: Datenaustausch!$AC$17:$AD$20
Name r_KostenVAR2: Datenaustausch!$AG$17:$AH$20
Name r_KostenVAR3: Datenaustausch!$AL$17:$AM$20

Sheet Allgemein
B2: Projektnummer: | D2: Zuständiger Sanierungslotse: | F2: =_xlfn.TEXTJOIN(" - ",TRUE,C2,RIGHT(C4,LEN(C4)-FIND(", ",C4)-1)) -> #VALUE! | L2: Bild von Haus!!! | O2: #VALUE!
B3: Anrede:
B4: Vorname Nachname: | D4: Zuständiger Energieberater:
B5: Straße, Nr. (Objektadresse): | F5: Kurzbeschreibung: | I5: Sanierung EFH
B6: PLZ, Ort: | D6: =IF(AND(C5<>"",C6<>""), HYPERLINK("https://www.google.com/maps/search/"&_xlfn.TEXTBEFORE(C6," ")&"+"&_xlfn.TEXTAFTER(C6," ")&"+"&C5, "Projekt in Maps anzeigen"), "")
B7: Email: | F7: Preis Gesamt: | I7: =J104 -> 0
B8: Telefon: | D8: besondere technische Zuwendung:
B9: Sharepoint | C9: Airteam | D9: Magicplan
E10: Legende: | F10: Energieberater | G10: Kalkulator | H10: Sanierungslotse
B11: Allgemeines Bestand:
B12: Gebäude | F12: Geschosse | J12: Strom und Heizkosten
B13: Gebäudebezeichnung: | D13: Gebäudetyp: | F13: Geschoss | G13: Anzahl | H13: lichte Raumhöhe | I13: Geschosshöhe | J13: Stromkosten
B14: Wohnfläche [m²]: | D14: Baujahr: | J14: Vebrauch Strom [kWh/Jahr]: | M14: Kosten Strom [€/kWh]:
B15: Wohneinheiten: | D15: Denkmalschutz: | J15: Heizkosten
B16: Anzahl der Personen: | D16: Beschreibung Denkmalschutz: | J16: Energieträger: | M16: Abrechnungseinheit:
B17: Kubatur: | J17: =_xlfn.TEXTJOIN(,,"Vebrauch Heizung [",O16,"/Jahr]:") -> Vebrauch Heizung [/Jahr]: | M17: =_xlfn.TEXTJOIN(,,"Kosten Heizung [€/",O16,"]:") -> Kosten Heizung [€/]:
B18: Anbausituation:
B19: Grundfläche des Hauses [m²]: | D19: Haus Länge [m]: | J19: =_xlfn.TEXTJOIN(,,"Heizwert [kWh/",O16,"]:") -> Heizwert [kWh/]: | L19: {=_xlfn.XLOOKUP(L16&O16,Heizung[Heizmedium]&Heizung[Einheit],Heizung[Heizwert '[kWh/Einheit']])} -> 0 | M19: CO2 Emmisionen [g/kWh]: | O19: {=_xlfn.XLOOKUP(Allgemein!L16&Allgemein!O16,Heizung[Heizmedium]&Heizung[Einheit],Heizung[CO2 Emmisionen '[g/kWh']],"",0,1)} -> 0
B20: Zugang zur Baustelle | D20: Haus Breite [m]: | J20: (manuell wenn nicht in Datenbank) | M20: (manuell wenn nicht in Datenbank)
B21: Befahrbarkeit für Fahzeuge < 40t möglich? | D21: Beschreibung Baustellenzufahrt:
B22: Absperrung Zufahrt nötig?:
B23: Zufahrtsbreite von 3,5m gegeben?:
B24: Interesse des Kunden/ Wunsch
B25: Wunsch Kunde | D25: Ist-Aufbau | E25: Ist- U-Wert | F25: Energetische Bewertung | G25: GEG-/ BEG -Norm | I25: Sowieso-Kosten | J25: Begründung | L25: Notizen Datenaufnahme | O25: Besonderheiten Gebäude
B26: Dach: | D26: - | I26: =_xlfn.XLOOKUP(J26,'Datenbank-Preise'!B140:B149,'Datenbank-Preise'!C140:C149,0,0,1)*Dach!E11 -> 0 | J26: -
B27: Fassade: | D27: - | I27: =_xlfn.XLOOKUP(J27,'Datenbank-Preise'!E140:E148,'Datenbank-Preise'!F140:F148,0,0,1)*Fassade!$P$523 -> 0 | J27: -
B28: Fenster: | D28: - | I28: =_xlfn.XLOOKUP(J28,'Datenbank-Preise'!H140:H148,'Datenbank-Preise'!I140:I148,0,0,1)*Fenster!J12+IF(AND(Fenster!J15>=1,J28<>"-",J28<>""),Fenster!J15*'Datenbank-Preise'!O140,0) -> 0 | J28: -
B29: Boden (unterer Gebäudeabschluss): | D29: - | I29: 0 | J29: -
B30: Keller: | D30: - | I30: =_xlfn.XLOOKUP(Allgemein!J30,'Datenbank-Preise'!Q140:Q142,'Datenbank-Preise'!R140:R142,0,0,1)*'Boden u. Keller'!E14+_xlfn.XLOOKUP(Allgemein!J30,'Datenbank-Preise'!Q140:Q142,'Datenbank-Preise'!S140:S142,0,0,1)*'Boden u. Keller'!E15 -> 0 | J30: -
B31: Heizung: | D31: - | I31: =_xlfn.XLOOKUP(J31,'Datenbank-Preise'!K140:K148,'Datenbank-Preise'!L140:L148,0,0,1) -> 0 | J31: -
B32: Photovoltaik: | I32: =SUM(I26:I31) -> 0 | J32: Summe
B33: Sonstiges
B34: Interesse / Anmerkungen | C34: Internes Gespräch + Fragen fürs Erstgespräch | D34: Ergebnisse Erstgespräch | G34: Ergebnisse Zweitgespräch | K34: Änderungsprotokollierung
B36: Ausgangszustand
B37: Ausgangswerte für Wirtschaftlichkeitsberechnung
B38: Primärenergiebedarf: | D38: kWh/m²a | E38: Endenergiebedarf Gerechnet: | H38: kWh/m²a | I38: Heizwärmemenge: | K38: =G40*C40 -> #DIV/0! | L38: kWh/a | M38: Vebrauch Strom [kWh/Jahr]: | O38: =L14 -> 0 | P38: kWh/a
B39: Heizwärmebedarf Nach Berechnung: | D39: kWh/m²a | E39: Endenergiebedarf Nach Verbrauch: | G39: =L19*L17/C40 -> #DIV/0! | H39: kWh/m²a | I39: Heizpreis pro kWh: | K39: =O17/L19 -> #DIV/0! | L39: /kWh | M39: Kosten Strom [€/kWh]: | O39: =O14 -> 0 | P39: /kWh
B40: Gebäudenutzfläche [Grundlage iSFP, Energieausweis]: | D40: m² | E40: Endenergiebedarf Annahme (Wirtschaftlichkeit): | G40: =G39 -> #DIV/0! | H40: kWh/m²a | I40: Heizkosten pro Jahr: | K40: =K38*K39 -> #DIV/0! | L40: /a | M40: Stromkosten [€/Jahr]: | O40: =L14*O14 -> 0 | P40: /a
B41: Varianten | F41: U-Wert Tabelle nach BEG
B42: iSFP | K42: BEG WG + Kredite:
...

Sheet Datenbank-Preise
B2: Dach
B4: Position Dach | C4: Dacheindeckung: | D4: Dämmung Dachschrägen: | E4: Dämmung obere Geschossdecke: | F4: Trockenbau innen: | G4: Dachstuhl Neu komplett: | L4: Pro Position | M4: Einheit | N4: Preis Brutto | O4: Menge | P4: iSFP | Q4: Menge | R4: Variante 1 | S4: Menge | T4: Variante 2
B5: - | C5: Nein | D5: Nein | E5: Nein | F5: Nein | G5: Nein | L5: Dacheindeckung: | M5: m² | N5: 270 | O5: =Dach!I12 -> 0 | P5: =IF(Dach!I11="Nein",0,N5*O5) -> 0 | Q5: =Dach!J12 -> 0 | R5: =IF(Dach!J11="Nein",0,Q5*'Datenbank-Preise'!$N$5) -> 0 | S5: =Dach!K12 -> 0 | T5: =IF(Dach!K11="Nein",0,S5*'Datenbank-Preise'!$N$5) -> 0
B6: Dacheindeckung + Dämmung Schrägen (außen) | C6: Ja | D6: Ja | E6: Nein | F6: Nein | G6: Nein | L6: Dämmung Dachschrägen: | M6: m² | N6: 100 | O6: =Dach!I16 -> 0 | P6: =IF(Dach!I14="Nein",0,O6*N6) -> 0 | Q6: =Dach!J16 -> 0 | R6: =IF(Dach!J14="Nein",0,Q6*'Datenbank-Preise'!$N6) -> 0 | S6: =Dach!K16 -> 0 | T6: =IF(Dach!K14="Nein",0,S6*'Datenbank-Preise'!$N6) -> 0
B7: Dacheindeckung + Dämmung Schrägen (außen) + Dämmung obere Geschossdecke | C7: Ja | D7: Ja | E7: Ja | F7: Nein | G7: Nein | L7: Trockenbau innen | M7: m² | N7: 90 | O7: =Dach!I20 -> 0 | P7: =IF(Dach!I19="Nein",0,O7*'Datenbank-Preise'!$N7) -> 0 | Q7: =Dach!J20 -> 0 | R7: =IF(Dach!J19="Nein",0,Q7*'Datenbank-Preise'!$N7) -> 0 | S7: =Dach!K20 -> 0 | T7: =IF(Dach!K19="Nein",0,S7*'Datenbank-Preise'!$N7) -> 0
B8: Dämmung Schrägen mit Trockenbau (innen) + Dämmung obere Geschossdecke | C8: Nein | D8: Ja | E8: Ja | F8: Ja | G8: Nein | L8: Dämmung obere Geschossdecke | M8: m² | N8: 110 | O8: =Dach!I23 -> 0 | P8: =IF(Dach!I22="Nein",0,O8*'Datenbank-Preise'!$N8) -> 0 | Q8: =Dach!J23 -> 0 | R8: =IF(Dach!J22="Nein",0,Q8*'Datenbank-Preise'!$N8) -> 0 | S8: =Dach!K23 -> 0 | T8: =IF(Dach!K22="Nein",0,S8*'Datenbank-Preise'!$N8) -> 0
B9: Dämmung Schrägen mit Trockenbau (innen) | C9: Nein | D9: Ja | E9: Nein | F9: Ja | G9: Nein | L9: Dachstuhl Neu komplett | M9: m² | N9: 200 | O9: =Dach!I27 -> 0 | P9: =IF(Dach!I26="Nein",0,O9*'Datenbank-Preise'!$N9) -> 0 | Q9: =Dach!J27 -> 0 | R9: =IF(Dach!J26="Nein",0,Q9*'Datenbank-Preise'!$N9) -> 0 | S9: =Dach!K27 -> 0 | T9: =IF(Dach!K26="Nein",0,S9*'Datenbank-Preise'!$N9) -> 0
B10: Dämmung obere Geschossdecke | C10: Nein | D10: Nein | E10: Ja | F10: Nein | G10: Nein | L10: Gauben bei neuer Dachdeckung | M10: Stk. | N10: 5500 | O10: =Dach!I31 -> 0 | P10: =IF(Dach!I11="Nein",0,O10*'Datenbank-Preise'!$N10) -> 0 | Q10: =Dach!J31 -> 0 | R10: =IF(Dach!J11="Nein",0,Q10*'Datenbank-Preise'!$N10) -> 0 | S10: =Dach!K31 -> 0 | T10: =IF(Dach!K11="Nein",0,S10*'Datenbank-Preise'!$N10) -> 0
B11: Dacheindeckung + Dämmung Schrägen mit Trockenbau (innen) + Dämmung obere Geschossdecke | C11: Ja | D11: Ja | E11: Ja | F11: Ja | G11: Nein | L11: Dachflächenfenster | M11: Stk. | N11: 3800 | O11: =(Dach!I35+Dach!I36) -> 0 | P11: =O11*'Datenbank-Preise'!$N11 -> 0 | Q11: =(Dach!J35+Dach!J36) -> 0 | R11: =Q11*'Datenbank-Preise'!$N11 -> 0 | S11: =(Dach!K35+Dach!K36) -> 0 | T11: =S11*'Datenbank-Preise'!$N11 -> 0
B12: Dacheindeckung + Dämmung Schrägen mit Trockenbau (innen) | C12: Ja | D12: Ja | E12: Nein | F12: Ja | G12: Nein
B13: Dachstuhl neu | C13: Ja | D13: Ja | E13: Nein | F13: Ja | G13: Ja | P13: =SUBTOTAL(109,'Datenbank-Preise'!$P$5:$P$12) -> 0 | R13: =SUBTOTAL(109,'Datenbank-Preise'!$R$5:$R$12) -> 0 | T13: =SUBTOTAL(109,'Datenbank-Preise'!$T$5:$T$12) -> 0
B14: Dacheindeckung + Dämmung obere Geschossdecke | C14: Ja | D14: Nein | E14: Ja | F14: Nein | G14: Nein
B15: Sonstiges | C15: Nein | D15: Nein | E15: Nein | F15: Nein | G15: Nein
B16: =Allgemein!C44 -> -
B17: =Allgemein!C60 -> -
B18: =Allgemein!C76 -> -
B22: Fassade
B24: Position Fassade | C24: WDVS: | D24: Einblasdämmung: | I24: Pro Position | J24: Einheit | K24: Preis Brutto | M24: Preisschätzung | N24: Menge | O24: iSFP | P24: Menge | Q24: Variante 1 | R24: Menge | S24: Variante 2
B25: WDVS Dämmung der Außenfassade mit Strukturputz | C25: Ja | D25: Nein | M25: WDVS | N25: =Fassade!V527 -> 0 | O25: =N25*_xlfn.XLOOKUP(Allgemein!D45,Tabelle43[Fassade],Tabelle43[Preis]) -> 0 | P25: =Fassade!W527 -> 0 | Q25: =P25*_xlfn.XLOOKUP(Allgemein!D61,Tabelle43[Fassade],Tabelle43[Preis]) -> 0 | R25: =Fassade!X527 -> 0 | S25: =R25*_xlfn.XLOOKUP(Allgemein!D77,Tabelle43[Fassade],Tabelle43[Preis]) -> 0
B26: WDVS Dämmung der Außenfassade mit Strukturputz + Einblasdämmung | C26: Ja | D26: Ja | I26: Einblasdämmung | J26: m² | K26: 100 | M26: Einblasdämmung | N26: =Fassade!V524 -> 0 | O26: =N26*'Datenbank-Preise'!$K26 -> 0 | P26: =Fassade!W524 -> 0 | Q26: =P26*'Datenbank-Preise'!$K26 -> 0 | R26: =Fassade!X524 -> 0 | S26: =R26*'Datenbank-Preise'!$K26 -> 0
B27: Einblasdämmung | C27: Nein | D27: Ja | M27: Ergebnis | O27: =SUBTOTAL(109,'Datenbank-Preise'!$O$25:$O$26) -> 0 | Q27: =SUBTOTAL(109,'Datenbank-Preise'!$Q$25:$Q$26) -> 0 | S27: =SUBTOTAL(109,'Datenbank-Preise'!$S$25:$S$26) -> 0
B28: - | C28: Nein | D28: Nein
B29: =Allgemein!C45 -> -
B30: =Allgemein!C61 -> -
B31: =Allgemein!C77 -> -
B35: Fenster
B37: Position Fenster | C37: Fensteraustausch: | D37: Türaustausch: | I37: Pro Position | J37: Einheit | K37: Preis Brutto | M37: Preisschätzung | N37: Menge | O37: iSFP | P37: Menge | Q37: Variante 1 | R37: Menge | S37: Variante 2
B38: - | C38: Nein | D38: Nein | I38: Fensteraustausch: | J38: m² | K38: 1350 | M38: Fensteraustausch | N38: =Fenster!M13 -> 0 | O38: =IF(N38="",0,'Datenbank-Preise'!$K38*N38) -> 0 | P38: =Fenster!N13 -> 0 | Q38: =IF(P38="",0,'Datenbank-Preise'!$K38*P38) -> 0 | R38: =Fenster!O13 -> 0 | S38: =IF(R38="",0,'Datenbank-Preise'!$K38*R38) -> 0
B39: Fenster + Terrassentüren inkl. Demontage, Entsorgung und Rollläden + Türaustausch | C39: Ja | D39: Ja | I39: Türaustausch: | J39: Stk. | K39: 4000 | M39: Türaustausch | N39: =Fenster!R13 -> 0 | O39: =IF(N39="",0,'Datenbank-Preise'!$K39*N39) -> 0 | P39: =Fenster!S13 -> 0 | Q39: =IF(P39="",0,'Datenbank-Preise'!$K39*P39) -> 0 | R39: =Fenster!T13 -> 0 | S39: =IF(R39="",0,'Datenbank-Preise'!$K39*R39) -> 0
B40: Türaustausch ohne Fenstersanierung | C40: Nein | D40: Ja | M40: Summe | O40: =SUM(O38:O39) -> 0 | Q40: =SUM(Q38:Q39) -> 0 | S40: =SUM(S38:S39) -> 0
B41: Fenster + Terrassentüren inkl. Demontage, Entsorgung und Rollläden | C41: Ja | D41: Nein
B42: =Allgemein!C46 -> -
B43: =Allgemein!C62 -> -
B44: =Allgemein!C78 -> -
B49: Boden (unterer Gebäudeabschluss)
B51: Position Keller | C51: Kellerdeckendämmung: | D51: Dämmung des Fußbodens: | E51: Einblasdämmung:
B52: - | C52: Nein | D52: Nein | E52: Nein | G52: Pro Position | H52: Einheit | I52: Preis Brutto | K52: Preisschätzung | L52: Menge | M52: iSFP | N52: Menge | O52: Variante 1 | P52: Menge | Q52: Variante 2
B53: Dämmung der Kellerdecke | C53: Ja | D53: Nein | E53: Nein | G53: Dämmung Kellerdecke | K53: Dämmung Kellerdecke | L53: ='Boden u. Keller'!G12 -> 0 | M53: =L53*_xlfn.XLOOKUP(Allgemein!D47,MiWo42[Keller und FB],MiWo42[Preis]) -> 0 | N53: ='Boden u. Keller'!H12 -> 0 | O53: =N53*_xlfn.XLOOKUP(Allgemein!D63,MiWo42[Keller und FB],MiWo42[Preis]) -> 0 | P53: ='Boden u. Keller'!I12 -> 0 | Q53: =P53*_xlfn.XLOOKUP(Allgemein!D79,MiWo42[Keller und FB],MiWo42[Preis]) -> 0
B54: Dämmung des Fußbodens | C54: Nein | D54: Ja | E54: Nein | G54: Dämmung Fußboden | H54: m² | I54: 245 | K54: Dämmung Fußboden | L54: ='Boden u. Keller'!G15 -> 0 | M54: =L54*'Datenbank-Preise'!$I$54 -> 0 | N54: ='Boden u. Keller'!H15 -> 0 | O54: =N54*'Datenbank-Preise'!$I$54 -> 0 | P54: ='Boden u. Keller'!I15 -> 0 | Q54: =P54*'Datenbank-Preise'!$I$54 -> 0
B55: Dämmung der Kellerdecke und des Fußbodens | C55: Ja | D55: Ja | E55: Nein | G55: Kellerdämmung (inkl. Abdichten) | H55: m² | I55: 300
...

Sheet Datenaustausch
B1: Allgemeine Angaben | AF1: Präsentation Erstgespräch | BH1: Präsentation Zweitgespräch
C4: =Allgemein!B2 -> Projektnummer: | D4: =Allgemein!C2 -> 0
C5: =Allgemein!B3 -> Anrede: | D5: =Allgemein!C3 -> 0
C6: =Allgemein!B4 -> Vorname Nachname: | D6: =Allgemein!C4 -> 0 | BR6: Primärenergiebedarf | BV6: Endenergiebedarf
C7: =Allgemein!B5 -> Straße, Nr. (Objektadresse): | D7: =Allgemein!C5 -> 0 | BR7: Vor Sanierung: | BS7: =Allgemein!C38 -> 0 | BT7: kWh/m²a | BV7: Vor Sanierung: | BW7: =Allgemein!G38 -> 0 | BX7: kWh/m²a
C8: =Allgemein!B6 -> PLZ, Ort: | D8: =Allgemein!C6 -> 0 | BR8: Nach Sanierung: | BS8: =Allgemein!C122 -> 0 | BT8: kWh/m²a | BV8: Nach Sanierung: | BW8: =Allgemein!C123 -> 0 | BX8: kWh/m²a
AQ9: Empfehlungsvariante | BJ9: Energetische Maßnahmen | BK9: Kosten
C10: Angaben | AC10: iSFP | AG10: Variante 1 | AL10: Variante 2 | BI10: Dach: | BJ10: =_xlfn.TEXTJOIN(" ",,Allgemein!C94,Allgemein!D94,IF(Allgemein!E94="",,"+"),Allgemein!E94) -> 0 0 | BK10: =Allgemein!E108 -> 0
C11: Beheizte Wohnfläche: | D11: =Allgemein!C14 -> 0 | E11: m² | BI11: Fassade: | BJ11: =_xlfn.TEXTJOIN(" ",,Allgemein!C95,Allgemein!D95,IF(Allgemein!E95="",,"+"),Allgemein!E95) -> 0 0 | BK11: =Allgemein!E109 -> 0
C12: Gebäudenutzfläche | D12: =Allgemein!C40 -> 0 | E12: m² | V12: Ausgangszustand - Sowieso-Kosten | BI12: Fenster: | BJ12: =_xlfn.TEXTJOIN(" ",,Allgemein!C96,Allgemein!D96,IF(Allgemein!E96="",,"+"),Allgemein!E96) -> 0 | BK12: =Allgemein!E110 -> 0 | BR12: Wirtschaftlichkeit
C13: Baujahr: | D13: =Allgemein!E14 -> 0 | AC13: Einsparung durch energetische Sanierung | AG13: Einsparung durch energetische Sanierung | AL13: Einsparung durch energetische Sanierung | AQ13: Einsparung durch energetische Sanierung | BI13: Boden / Keller: | BJ13: =_xlfn.TEXTJOIN(" ",,Allgemein!C97,Allgemein!D97,IF(Allgemein!E97="",,"+"),Allgemein!E97," / ",Allgemein!C98,Allgemein!D98,IF(Allgemein!E98="",,"+"),Allgemein!E98) -> 0 0 / 0 0 | BK13: =Allgemein!E112+Allgemein!E111 -> 0 | BR13: Einnahmen | BV13: Ausgaben
C14: Endenergiebedarf: | D14: =Allgemein!G38 -> 0 | E14: kWh/m²a | AC14: Einsparung der Strom- und Heizkosten über 30 Jahre: | AD14: =Datenbank!AN104 -> #DIV/0! | AG14: Einsparung der Strom- und Heizkosten über 30 Jahre: | AH14: =Datenbank!AN214 -> #DIV/0! | AL14: Einsparung der Strom- und Heizkosten über 30 Jahre: | AM14: =Datenbank!AN331 -> #DIV/0! | AQ14: Einsparung der Strom- und Heizkosten über 30 Jahre: | AR14: =Datenbank!AN446 -> #DIV/0! | BI14: Heizung: | BJ14: =_xlfn.TEXTJOIN(" ",,Allgemein!C100,IF(Allgemein!D100="",,"+"),Allgemein!D100,IF(Allgemein!E100="",,"+"),Allgemein!E100) -> 0 + 0 | BK14: =Allgemein!E114 -> 0 | BR14: Einsparung: | BS14: WENN(Allgemein!G94="";"";"/ ") | BV14: Kosten: | BW14: =Allgemein!L122 -> 0
C15: Primärenergiebedarf: | D15: =Allgemein!C38 -> 0 | E15: kWh/m²a | W15: Maßnahmen | X15: Sowieso-Kosten | Y15: Begründung | AD15: =SUM(AD14) -> #DIV/0! | AH15: =SUM(AH14) -> #DIV/0! | AM15: =SUM(AM14) -> #DIV/0! | AR15: =SUM(AR14) -> #DIV/0! | BI15: PV / Elektro: | BJ15: =_xlfn.TEXTJOIN(" ",TRUE,Allgemein!C101,"PV-Anlage","mit",Allgemein!D101,"Speichersystem",IF(Allgemein!E101="",,"+"),Allgemein!E101) -> 0 PV-Anlage mit 0 Speichersystem | BK15: =Allgemein!E115 -> 0 | BR15: geschätzte Wertsteigerung: | BS15: =Allgemein!L123 -> 0 | BV15: geschätzte Sowieso-Kosten: | BW15: =X74 -> 0
W16: Dach: | X16: =Allgemein!I26 -> 0 | Y16: =Allgemein!J26 -> - | BI16: Sonstiges: | BJ16: =_xlfn.TEXTJOIN(" ",,IF(Allgemein!C102="Dezentrale Lüftungsanlage",_xlfn.TEXTJOIN(" ",TRUE,Allgemein!C102,"("&Allgemein!D102,")"),Allgemein!C102),IF(Allgemein!E102="",,"+"),Allgemein!E102) -> 0 | BK16: =Allgemein!E116 -> 0 | BR16: Förderung: | BS16: =Allgemein!P123 -> 0 | BV16: Kreditkosten: | BW16: =Allgemein!N122 -> 0
C17: Heiz- und Stromenergie | G17: Heiz- und Stromkosten | W17: Fassade: | X17: =Allgemein!I27 -> 0 | Y17: =Allgemein!J27 -> - | AC17: Kosten der energetischen Sanierung | AG17: Kosten der energetischen Sanierung | AL17: Kosten der energetischen Sanierung | AQ17: Kosten der energetischen Sanierung | BI17: BRALE Energy: | BJ17: Begleitung durch Energieberater, Begleitung und Koordination durch Bauleiter, Schnittstellenversprechen, Förderservice, Festpreisgarantie, Bauzeitgarantie, Gewährleistung aus einer Hand | BK17: =Allgemein!E117 -> 0 | BS17: =SUM(BS14:BS16) -> 0 | BW17: =SUM(BW14,BW16) -> 0
C18: Haupt-Energieträger: | D18: =Allgemein!L16 -> 0 | G18: Stromkosten pro kWh: | H18: =Allgemein!O14 -> 0 | I18: € | W18: Fenster: | X18: =Allgemein!I28 -> 0 | Y18: =Allgemein!J28 -> - | AC18: Geschätzte energetische Sanierungskosten: | AD18: =Allgemein!G53 -> 0 | AG18: Geschätzte energetische Sanierungskosten: | AH18: =Allgemein!G69 -> 0 | AL18: Geschätzte energetische Sanierungskosten: | AM18: =Allgemein!G85 -> 0 | AQ18: Geschätzte energetische Sanierungskosten: | AR18: =Allgemein!E118 -> 0 | BI18: Gesamt: | BK18: =Allgemein!E118 -> 0
C19: angegebener Heizverbrauch: | D19: =Allgemein!L17 -> 0 | E19: =_xlfn.TEXTJOIN(,,Allgemein!O16,"/a") -> /a | G19: Stromkosten: | H19: =Allgemein!O40 -> 0 | I19: €/a | W19: Keller: | X19: =Allgemein!I30 -> 0 | Y19: =Allgemein!J30 -> - | AC19: Abzgl. geschätzte Förderung: | AD19: =-Allgemein!O54 -> 0 | AG19: Abzgl. geschätzte Förderung: | AH19: =-Allgemein!O70 -> 0 | AL19: Abzgl. geschätzte Förderung: | AM19: =-Allgemein!O86 -> 0 | AQ19: Abzgl. geschätzte Förderung: | AR19: =-Allgemein!N118 -> 0
C20: angenommener Heizverbrauch: | D20: =Allgemein!K38 -> #DIV/0! | E20: kWh/a | G20: Heizpreis pro kWh: | H20: =Allgemein!K39 -> #DIV/0! | I20: € | W20: Heizung: | X20: =Allgemein!I31 -> 0 | Y20: =Allgemein!J31 -> - | AD20: =SUM(AD18:AD19) -> 0 | AH20: =SUM(AH18:AH19) -> 0 | AM20: =SUM(AM18:AM19) -> 0 | AR20: =SUM(AR18:AR19) -> 0
C21: Endenergiebedarf nach Heizverbrauch: | D21: =ROUNDUP(Allgemein!G40,0) -> #DIV/0! | E21: kWh/m²a | G21: Heizkosten: | H21: =Allgemein!K40 -> #DIV/0! | I21: €/a | W21: Gesamt: | X21: =SUM(X16:X20) -> 0
C22: Stromverbrauch: | D22: =Allgemein!L14 -> 0 | E22: kWh/a | G22: Betriebskosten: | H22: =Allgemein!K40+Allgemein!O40 -> #DIV/0! | I22: €/a | AC22: Tatsächliche Kosten der energetischen Sanierung | AG22: Tatsächliche Kosten der energetischen Sanierung | AL22: Tatsächliche Kosten der energetischen Sanierung | AQ22: Tatsächliche Mehrkosten der energetischen Sanierung
AC23: Kosten der energetischen Sanierung: | AD23: =AD20 -> 0 | AG23: Kosten der energetischen Sanierung: | AH23: =AH20 -> 0 | AL23: Kosten der energetischen Sanierung: | AM23: =AM20 -> 0 | AQ23: Kosten der energetischen Sanierung: | AR23: =AR20 -> 0 | BR23: Zusammenfassend: | BS23: =BJ10 -> 0 0
I24: CO2 Auto km (120 g pro km) | J24: Um die Welt fahren | K24: Flug Berlin Nach Mallorca | AC24: Abzgl. der Sowieso-Kosten | AD24: =-X34 -> 0 | AG24: Abzgl. der Sowieso-Kosten | AH24: =-X46 -> 0 | AL24: Abzgl. der Sowieso-Kosten | AM24: =-X60 -> 0 | AQ24: Abzgl. der Sowieso-Kosten | AR24: =-Allgemein!P122 -> 0 | BR24: Zusammenfassend: | BS24: =BJ11 -> 0 0
C25: CO2-Verbrauch in 30 Jahre (Vor -Sanierung): | E25: =_xlfn.TEXTJOIN(,,H25," t") -> 0 t | H25: =ROUNDUP(Allgemein!L17*30*Allgemein!L19*Allgemein!O19/(1000*1000),0) -> 0 | I25: =H25*1000/0.12 -> 0 | J25: =_xlfn.TEXTJOIN("",,ROUNDUP(I25/40075,0)," x") -> 0 x | K25: =_xlfn.TEXTJOIN("",,ROUNDUP(H25/0.364,0), " x") -> 0 x | V25: iSFP - Sowieso-Kosten | AD25: =SUM(AD23:AD24) -> 0 | AH25: =SUM(AH23:AH24) -> 0 | AM25: =SUM(AM23:AM24) -> 0 | AR25: =SUM(AR23:AR24) -> 0 | BR25: Zusammenfassend: | BS25: =BJ12 -> 0
C26: CO2-Einsparung in 30 Jahre (Nach -Sanierung): | E26: =_xlfn.TEXTJOIN(,,H26," t") -> 0 t | H26: =ROUNDUP(IF(Allgemein!C132="JA",H25,H25-Allgemein!O19*Allgemein!C124*Allgemein!C14*30/(1000*1000)),0) -> 0 | I26: =H26*1000/0.12 -> 0 | J26: =_xlfn.TEXTJOIN(" ",,ROUNDUP(I26/40075,0),"x") -> 0 x | K26: =_xlfn.TEXTJOIN(" ",,ROUNDUP(H26/0.364,0),"x") -> 0 x | BR26: Zusammenfassend: | BS26: =_xlfn.TEXTJOIN(" ",,Allgemein!C97,Allgemein!D97,IF(Allgemein!E97="",,"+"),Allgemein!E97) -> 0 0
AC27: Einnahmen | AD27: Ausgaben | AG27: Einnahmen | AH27: Ausgaben | AL27: Einnahmen | AM27: Ausgaben | AQ27: Einsparung | AR27: Kosten | BR27: Zusammenfassend: | BS27: =_xlfn.TEXTJOIN(" ",,Allgemein!C98,Allgemein!D98,IF(Allgemein!E98="",,"+"),Allgemein!E98) -> 0 0
C28: Endenergiebedarf vor Sanierung | W28: Maßnahmen | X28: Sowieso-Kosten | Y28: Begründung | AB28: Kosten | AD28: =AD25 -> 0 | AF28: Kosten | AH28: =AH25 -> 0 | AK28: Kosten | AM28: =AM25 -> 0 | AP28: Kosten | AR28: =AR25 -> 0 | BR28: Zusammenfassend: | BS28: =Allgemein!C99 -> nicht festgelegt
D29: Vor Sanierung | E29: =IF(Allgemein!G38>250,250,Allgemein!G38) -> 0 | F29: 0 | W29: Dach: | X29: =IF(OR(Allgemein!C44="-",Allgemein!C44=""),0,Allgemein!$I$26) -> 0 | Y29: =IF(OR(Allgemein!C44="-",Allgemein!C44=""),"",Allgemein!$J$26) | AB29: Einsparung | AC29: =Datenbank!AN104 -> #DIV/0! | AF29: Einsparung | AG29: =Datenbank!AN214 -> #DIV/0! | AK29: Einsparung | AL29: =Datenbank!AN331 -> #DIV/0! | AP29: Einsparung | AQ29: =Datenbank!AN446 -> #DIV/0! | BR29: Zusammenfassend: | BS29: =BJ14 -> 0 + 0
W30: Fassade: | X30: =IF(OR(Allgemein!C45="-",Allgemein!C45=""),0,Allgemein!$I$27) -> 0 | Y30: =IF(OR(Allgemein!C45="-",Allgemein!C45=""),"",Allgemein!$J$27) | BI30: Maßnahmenpakete | BJ30: Kosten | BK30: Fördersatz | BL30: Förderbar | BM30: Zuschuss | BR30: Zusammenfassend: | BS30: =BJ15 -> 0 PV-Anlage mit 0 Speichersystem
I31: Ersparniss: | J31: =Datenbank!AJ460 -> #DIV/0! | W31: Fenster: | X31: =IF(OR(Allgemein!C46="-",Allgemein!C46=""),0,Allgemein!$I$28) -> 0 | Y31: =IF(OR(Allgemein!C46="-",Allgemein!C46=""),"",Allgemein!$J$28) | AC31: Einsparung: | AD31: =AD15 -> #DIV/0! | AG31: Einsparung: | AH31: =AH15 -> #DIV/0! | AL31: Einsparung: | AM31: =AM15 -> #DIV/0! | AQ31: Einsparung: | AR31: =AR15 -> #DIV/0! | BI31: Gebäudehülle (BAFA): | BJ31: =Allgemein!E113 -> 0 | BK31: =Allgemein!G113 -> 0 | BL31: =Allgemein!H113 -> 0 | BM31: =Allgemein!I113 -> 0 | BR31: Zusammenfassend: | BS31: =BJ16 -> 0
J32: =Allgemein!C126 -> 0 | W32: Keller: | X32: =IF(OR(Allgemein!C48="-",Allgemein!C48=""),0,Allgemein!$I$30) -> 0 | Y32: =IF(OR(Allgemein!C48="-",Allgemein!C48=""),"",Allgemein!$J$30) | AC32: Kosten: | AD32: =-AD25 -> 0 | AG32: Kosten: | AH32: =-AH25 -> 0 | AL32: Kosten: | AM32: =-AM25 -> 0 | AQ32: Kosten: | AR32: =-AR25 -> 0 | BI32: Dach: | BK32: {=Allgemein!G108:G111} -> 0 | BL32: {=Allgemein!H108:H111} -> 0 | BM32: {=Allgemein!I108:I111} -> 0
I33: Strom und Heizkosten in den nächsten 30 Jahren ohne Sanierung | J33: =Datenbank!AI447 -> #DIV/0! | W33: Heizung: | X33: =IF(OR(Allgemein!C50="-",Allgemein!C50=""),0,Allgemein!$I$31) -> 0 | Y33: =IF(OR(Allgemein!C50="-",Allgemein!C50=""),"",Allgemein!$J$31) | AC33: + | AD33: =AD15-AD25 -> #DIV/0! | AG33: + | AH33: =AH15-AH25 -> #DIV/0! | AL33: + | AM33: =AM15-AM25 -> #DIV/0! | AQ33: + | AR33: =AR15-r_tatKostenEinzelnEMPF -> #DIV/0! | BI33: Fassade: | BK33: 0 | BL33: 0 | BM33: 0
I34: Strom und Heizkosten in den nächsten 30 Jahren mit Sanierung | J34: =Datenbank!AI460 -> #DIV/0! | W34: Gesamt: | X34: =SUM(X29:X33) -> 0 | BI34: Fenster: | BK34: 0 | BL34: 0 | BM34: 0 | BR34: Wirtschaftlichkeit Empfehlungsvariante | BW34: Wirtschaftlichkeit Empfehlungsvariante
BI35: Boden (unterer Gebäudeabschluss): | BK35: 0 | BL35: 0 | BM35: 0 | BS35: Instandhaltung (Sowieso-Kosten) | BT35: Energetische Sanierung | BW35: Jahr | BX35: Mehrkosten im Monat
BI36: Keller: | BK36: =Allgemein!G112 -> 0 | BL36: =Allgemein!H112 -> 0 | BM36: =Allgemein!I112 -> 0 | BR36: Kosten: | BS36: =Allgemein!P122 -> 0 | BT36: =AR20 -> 0 | BW36: 1. Jahr
V37: Variante 1 - Sowieso-Kosten | BI37: Heizung (KfW): | BJ37: =Allgemein!E114 -> 0 | BK37: =Allgemein!G114 -> 0 | BL37: =Allgemein!H114 -> 0 | BM37: =Allgemein!I114 -> 0 | BR37: Heizkosten pro Monat (1. Jahr): | BS37: =Datenbank!D448 -> #DIV/0! | BT37: =Datenbank!D458 -> #DIV/0! | BW37: 5. Jahr
BI38: Direktzuschuss: | BL38: =Allgemein!I118 -> 0 | BR38: Kreditkosten pro Monat: | BS38: =BS36*0.058/12 -> 0 | BT38: =BT36*0.058/12 -> 0 | BW38: 10. Jahr
BR39: Gesamtkosten pro Monat (1. Jahr): | BS39: =SUM(BS37:BS38) -> #DIV/0! | BT39: =SUM(BT37:BT38) -> #DIV/0! | BW39: 20. Jahr
W40: Maßnahmen | X40: Sowieso-Kosten | Y40: Begründung | BW40: 30. Jahr
W41: Dach: | X41: =IF(OR(Allgemein!C60="-",Allgemein!C60=""),0,Allgemein!$I$26) -> 0 | Y41: =IF(OR(Allgemein!C60="-",Allgemein!C60=""),"",Allgemein!$J$26) | BI41: Geförderte Maßnahmen | BJ41: Förderbar | BK41: Kredit | BL41: Zinssatz | BM41: Laufzeit
F42: Kosten pro Monat vor Sanierung | W42: Fassade: | X42: =IF(OR(Allgemein!C61="-",Allgemein!C61=""),0,Allgemein!$I$27) -> 0 | Y42: =IF(OR(Allgemein!C61="-",Allgemein!C61=""),"",Allgemein!$J$27) | BI42: =Allgemein!K108 -> 0 | BJ42: =Allgemein!H115 -> 0 | BK42: =Allgemein!K110 -> 0 | BL42: =Allgemein!K112 -> 0 | BM42: =Allgemein!K113 -> 0
...

Sheet Fassade
B2: Projektnummer: | C2: =Allgemein!C2 -> 0 | F2: Maßnahmenpaket Fassade | U2: #VALUE!
B3: Anrede: | C3: =Allgemein!C3 -> 0 | L3: Kurzbeschreibung Maßnahmen
B4: Vorname Nachname: | C4: =Allgemein!C4 -> 0 | F4: Umsetzungsvariante: | L4: =Allgemein!C95 -> 0
B5: Straße, Nr. (Objektadresse): | C5: =Allgemein!C5 -> 0 | F5: Zusatzleistung: | L5: =Allgemein!G95 -> 0
B6: PLZ, Ort: | C6: =Allgemein!C6 -> 0 | F6: Variante 1: | L6: =Allgemein!C45 -> -
B7: Email: | C7: =Allgemein!C7 -> 0 | F7: Variante 2: | L7: =Allgemein!C61 -> -
B8: Telefon: | C8: =Allgemein!C8 -> 0 | F8: Variante 3: | L8: =Allgemein!C77 -> -
B9: Wandtypen | U9: Sicherheitsfaktor allgemein: | V9: 1.05
B10: Bestand | F10: Wände | S10: Wunsch/Anmerkung | U10: Umsetzung | V10: iSFP | W10: Variante 1 | X10: Variante 2
B11: Monolithisches Mauerwerk | D11: #VALUE! | F11: Benennung | G11: Beschreibung | H11: Breite [m] | I11: Höhe [m] | J11: Zusatzfläche (Bsp. Giebel) | K11: Anmerkung Zusatzfläche | L11: Brutto- fläche [m²] | M11: Anzahl Öffnungen | N11: Öffnungs- fläche [m²] | O11: Öffnungs- fläche über 2,5 m² [m²] | P11: Umfang Öffnungen [m] | Q11: Kalkulatorische Fläche [m²] | R11: Nettofläche zu dämmen [m²] | U11: WDVS: | V11: {=_xlfn.XLOOKUP(U11&Allgemein!$C$45,Fassadenpositionen[[#Headers],[WDVS:]]&Fassadenpositionen[Position Fassade],Fassadenpositionen[WDVS:],"",0,1)} -> Nein | W11: {=_xlfn.XLOOKUP(U11&Allgemein!$C$61,Fassadenpositionen[[#Headers],[WDVS:]]&Fassadenpositionen[Position Fassade],Fassadenpositionen[WDVS:],"",0,1)} -> Nein | X11: {=_xlfn.XLOOKUP(U11&Allgemein!$C$77,Fassadenpositionen[[#Headers],[WDVS:]]&Fassadenpositionen[Position Fassade],Fassadenpositionen[WDVS:],"",0,1)} -> Nein
B12: Außenwandtyp_xx | L12: =H12*I12+J12 -> 0 | M12: =SUMIF(Fenster!$D$10:$D$2160,Fassade!F12,Fenster!$J$10:$J$2160) -> 0 | N12: =SUMIF(Fenster!$D$10:$D$2160,Fassade!F12,Fenster!$M$10:$M$2160) -> 0 | O12: =SUMIFS(Fenster!$M$10:$M$2160,Fenster!$D$10:$D$2160,Fassade!F12,Fenster!$L$10:$L$2160,">2,5") -> 0 | P12: =SUMIF(Fenster!$D$10:$D$2160,Fassade!F12,Fenster!$K$10:$K$2160) -> 0 | Q12: =L12-O12 -> 0 | R12: =L12-N12 -> 0 | U12: Zusatz oder Abzugsfläche [m²]: | V12: 0 | W12: 0 | X12: 0
B13: Material Außenwand (1): | L13: =H13*I13+J13 -> 0 | M13: =SUMIF(Fenster!$D$10:$D$2160,Fassade!F13,Fenster!$J$10:$J$2160) -> 0 | N13: =SUMIF(Fenster!$D$10:$D$2160,Fassade!F13,Fenster!$M$10:$M$2160) -> 0 | O13: =SUMIFS(Fenster!$M$10:$M$2160,Fenster!$D$10:$D$2160,Fassade!F13,Fenster!$L$10:$L$2160,">2,5") -> 0 | P13: =SUMIF(Fenster!$D$10:$D$2160,Fassade!F13,Fenster!$K$10:$K$2160) -> 0 | Q13: =L13-O13 -> 0 | R13: =L13-N13 -> 0 | U13: Kalkulatorische Fläche: | V13: =IF(V11="Ja",(Q22+V12)*$V$9,0) -> 0 | W13: =IF(W11="Ja",(Q22+W12)*$V$9,0) -> 0 | X13: =IF(X11="Ja",(Q22+X12)*$V$9,0) -> 0
B14: Stärke Außenwand (1) [cm]: | L14: =H14*I14+J14 -> 0 | M14: =SUMIF(Fenster!$D$10:$D$2160,Fassade!F14,Fenster!$J$10:$J$2160) -> 0 | N14: =SUMIF(Fenster!$D$10:$D$2160,Fassade!F14,Fenster!$M$10:$M$2160) -> 0 | O14: =SUMIFS(Fenster!$M$10:$M$2160,Fenster!$D$10:$D$2160,Fassade!F14,Fenster!$L$10:$L$2160,">2,5") -> 0 | P14: =SUMIF(Fenster!$D$10:$D$2160,Fassade!F14,Fenster!$K$10:$K$2160) -> 0 | Q14: =L14-O14 -> 0 | R14: =L14-N14 -> 0 | U14: Nettofläche zu dämmen: | V14: =IF(V11="Ja",(R22+V12)*$V$9,0) -> 0 | W14: =IF(W11="Ja",(R22+W12)*$V$9,0) -> 0 | X14: =IF(X11="Ja",(R22+X12)*$V$9,0) -> 0
B15: U-Wert [W/(m²K)]: | L15: =H15*I15+J15 -> 0 | M15: =SUMIF(Fenster!$D$10:$D$2160,Fassade!F15,Fenster!$J$10:$J$2160) -> 0 | N15: =SUMIF(Fenster!$D$10:$D$2160,Fassade!F15,Fenster!$M$10:$M$2160) -> 0 | O15: =SUMIFS(Fenster!$M$10:$M$2160,Fenster!$D$10:$D$2160,Fassade!F15,Fenster!$L$10:$L$2160,">2,5") -> 0 | P15: =SUMIF(Fenster!$D$10:$D$2160,Fassade!F15,Fenster!$K$10:$K$2160) -> 0 | Q15: =L15-O15 -> 0 | R15: =L15-N15 -> 0 | U15: Material, Stärke: | V15: =Allgemein!$D$45 -> - | W15: =Allgemein!$D$61 -> - | X15: =Allgemein!$D$77 -> -
B16: Beschreibung Wandtyp: | L16: =H16*I16+J16 -> 0 | M16: =SUMIF(Fenster!$D$10:$D$2160,Fassade!F16,Fenster!$J$10:$J$2160) -> 0 | N16: =SUMIF(Fenster!$D$10:$D$2160,Fassade!F16,Fenster!$M$10:$M$2160) -> 0 | O16: =SUMIFS(Fenster!$M$10:$M$2160,Fenster!$D$10:$D$2160,Fassade!F16,Fenster!$L$10:$L$2160,">2,5") -> 0 | P16: =SUMIF(Fenster!$D$10:$D$2160,Fassade!F16,Fenster!$K$10:$K$2160) -> 0 | Q16: =L16-O16 -> 0 | R16: =L16-N16 -> 0 | U16: Bemerkung:
B17: Kellerwand?: | L17: =H17*I17+J17 -> 0 | M17: =SUMIF(Fenster!$D$10:$D$2160,Fassade!F17,Fenster!$J$10:$J$2160) -> 0 | N17: =SUMIF(Fenster!$D$10:$D$2160,Fassade!F17,Fenster!$M$10:$M$2160) -> 0 | O17: =SUMIFS(Fenster!$M$10:$M$2160,Fenster!$D$10:$D$2160,Fassade!F17,Fenster!$L$10:$L$2160,">2,5") -> 0 | P17: =SUMIF(Fenster!$D$10:$D$2160,Fassade!F17,Fenster!$K$10:$K$2160) -> 0 | Q17: =L17-O17 -> 0 | R17: =L17-N17 -> 0
L18: =H18*I18+J18 -> 0 | M18: =SUMIF(Fenster!$D$10:$D$2160,Fassade!F18,Fenster!$J$10:$J$2160) -> 0 | N18: =SUMIF(Fenster!$D$10:$D$2160,Fassade!F18,Fenster!$M$10:$M$2160) -> 0 | O18: =SUMIFS(Fenster!$M$10:$M$2160,Fenster!$D$10:$D$2160,Fassade!F18,Fenster!$L$10:$L$2160,">2,5") -> 0 | P18: =SUMIF(Fenster!$D$10:$D$2160,Fassade!F18,Fenster!$K$10:$K$2160) -> 0 | Q18: =L18-O18 -> 0 | R18: =L18-N18 -> 0
L19: =H19*I19+J19 -> 0 | M19: =SUMIF(Fenster!$D$10:$D$2160,Fassade!F19,Fenster!$J$10:$J$2160) -> 0 | N19: =SUMIF(Fenster!$D$10:$D$2160,Fassade!F19,Fenster!$M$10:$M$2160) -> 0 | O19: =SUMIFS(Fenster!$M$10:$M$2160,Fenster!$D$10:$D$2160,Fassade!F19,Fenster!$L$10:$L$2160,">2,5") -> 0 | P19: =SUMIF(Fenster!$D$10:$D$2160,Fassade!F19,Fenster!$K$10:$K$2160) -> 0 | Q19: =L19-O19 -> 0 | R19: =L19-N19 -> 0
L20: =H20*I20+J20 -> 0 | M20: =SUMIF(Fenster!$D$10:$D$2160,Fassade!F20,Fenster!$J$10:$J$2160) -> 0 | N20: =SUMIF(Fenster!$D$10:$D$2160,Fassade!F20,Fenster!$M$10:$M$2160) -> 0 | O20: =SUMIFS(Fenster!$M$10:$M$2160,Fenster!$D$10:$D$2160,Fassade!F20,Fenster!$L$10:$L$2160,">2,5") -> 0 | P20: =SUMIF(Fenster!$D$10:$D$2160,Fassade!F20,Fenster!$K$10:$K$2160) -> 0 | Q20: =L20-O20 -> 0 | R20: =L20-N20 -> 0
L21: =H21*I21+J21 -> 0 | M21: =SUMIF(Fenster!$D$10:$D$2160,Fassade!F21,Fenster!$J$10:$J$2160) -> 0 | N21: =SUMIF(Fenster!$D$10:$D$2160,Fassade!F21,Fenster!$M$10:$M$2160) -> 0 | O21: =SUMIFS(Fenster!$M$10:$M$2160,Fenster!$D$10:$D$2160,Fassade!F21,Fenster!$L$10:$L$2160,">2,5") -> 0 | P21: =SUMIF(Fenster!$D$10:$D$2160,Fassade!F21,Fenster!$K$10:$K$2160) -> 0 | Q21: =L21-O21 -> 0 | R21: =L21-N21 -> 0
F22: Summe: | L22: =SUM(L12:L21) -> 0 | M22: =SUM(M12:M21) -> 0 | N22: =SUM(N12:N21) -> 0 | O22: =SUM(O12:O21) -> 0 | P22: =SUM(P12:P21) -> 0 | Q22: =SUM(Q12:Q21) -> 0 | R22: =SUM(R12:R21) -> 0
B24: Monolithisches Mauerwerk | D24: #VALUE! | F24: Benennung | G24: Beschreibung | H24: Breite [m] | I24: Höhe [m] | J24: Zusatzfläche (Bsp. Giebel) | K24: Anmerkung Zusatzfläche | L24: Brutto- fläche [m²] | M24: Anzahl Öffnungen | N24: Öffnungs- fläche [m²] | O24: Öffnungs- fläche über 2,5 m² [m²] | P24: Umfang Öffnungen [m] | Q24: Kalkulatorische Fläche [m²] | R24: Nettofläche zu dämmen [m²] | U24: WDVS: | V24: {=_xlfn.XLOOKUP(U24&Allgemein!$C$45,Fassadenpositionen[[#Headers],[WDVS:]]&Fassadenpositionen[Position Fassade],Fassadenpositionen[WDVS:],"",0,1)} -> Nein | W24: {=_xlfn.XLOOKUP(U24&Allgemein!$C$61,Fassadenpositionen[[#Headers],[WDVS:]]&Fassadenpositionen[Position Fassade],Fassadenpositionen[WDVS:],"",0,1)} -> Nein | X24: {=_xlfn.XLOOKUP(U24&Allgemein!$C$77,Fassadenpositionen[[#Headers],[WDVS:]]&Fassadenpositionen[Position Fassade],Fassadenpositionen[WDVS:],"",0,1)} -> Nein
B25: Außenwandtyp_xx | L25: =H25*I25+J25 -> 0 | M25: =SUMIF(Fenster!$D$10:$D$2160,Fassade!F25,Fenster!$J$10:$J$2160) -> 0 | N25: =SUMIF(Fenster!$D$10:$D$2160,Fassade!F25,Fenster!$M$10:$M$2160) -> 0 | O25: =SUMIFS(Fenster!$M$10:$M$2160,Fenster!$D$10:$D$2160,Fassade!F25,Fenster!$L$10:$L$2160,">2,5") -> 0 | P25: =SUMIF(Fenster!$D$10:$D$2160,Fassade!F25,Fenster!$K$10:$K$2160) -> 0 | Q25: =L25-O25 -> 0 | R25: =L25-N25 -> 0 | U25: Zusatz oder Abzugsfläche [m²]: | V25: 0 | W25: 0 | X25: 0
B26: Material Außenwand (1): | L26: =H26*I26+J26 -> 0 | M26: =SUMIF(Fenster!$D$10:$D$2160,Fassade!F26,Fenster!$J$10:$J$2160) -> 0 | N26: =SUMIF(Fenster!$D$10:$D$2160,Fassade!F26,Fenster!$M$10:$M$2160) -> 0 | O26: =SUMIFS(Fenster!$M$10:$M$2160,Fenster!$D$10:$D$2160,Fassade!F26,Fenster!$L$10:$L$2160,">2,5") -> 0 | P26: =SUMIF(Fenster!$D$10:$D$2160,Fassade!F26,Fenster!$K$10:$K$2160) -> 0 | Q26: =L26-O26 -> 0 | R26: =L26-N26 -> 0 | U26: Kalkulatorische Fläche: | V26: =IF(V24="Ja",(Q35+V25)*$V$9,0) -> 0 | W26: =IF(W24="Ja",(Q35+W25)*$V$9,0) -> 0 | X26: =IF(X24="Ja",(Q35+X25)*$V$9,0) -> 0
B27: Stärke Außenwand (1) [cm]: | L27: =H27*I27+J27 -> 0 | M27: =SUMIF(Fenster!$D$10:$D$2160,Fassade!F27,Fenster!$J$10:$J$2160) -> 0 | N27: =SUMIF(Fenster!$D$10:$D$2160,Fassade!F27,Fenster!$M$10:$M$2160) -> 0 | O27: =SUMIFS(Fenster!$M$10:$M$2160,Fenster!$D$10:$D$2160,Fassade!F27,Fenster!$L$10:$L$2160,">2,5") -> 0 | P27: =SUMIF(Fenster!$D$10:$D$2160,Fassade!F27,Fenster!$K$10:$K$2160) -> 0 | Q27: =L27-O27 -> 0 | R27: =L27-N27 -> 0 | U27: Nettofläche zu dämmen: | V27: =IF(V24="Ja",(R35+V25)*$V$9,0) -> 0 | W27: =IF(W24="Ja",(R35+W25)*$V$9,0) -> 0 | X27: =IF(X24="Ja",(R35+X25)*$V$9,0) -> 0
B28: U-Wert [W/(m²K)]: | L28: =H28*I28+J28 -> 0 | M28: =SUMIF(Fenster!$D$10:$D$2160,Fassade!F28,Fenster!$J$10:$J$2160) -> 0 | N28: =SUMIF(Fenster!$D$10:$D$2160,Fassade!F28,Fenster!$M$10:$M$2160) -> 0 | O28: =SUMIFS(Fenster!$M$10:$M$2160,Fenster!$D$10:$D$2160,Fassade!F28,Fenster!$L$10:$L$2160,">2,5") -> 0 | P28: =SUMIF(Fenster!$D$10:$D$2160,Fassade!F28,Fenster!$K$10:$K$2160) -> 0 | Q28: =L28-O28 -> 0 | R28: =L28-N28 -> 0 | U28: Material, Stärke: | V28: =Allgemein!$D$45 -> - | W28: =Allgemein!$D$61 -> - | X28: =Allgemein!$D$77 -> -
B29: Beschreibung Wandtyp: | L29: =H29*I29+J29 -> 0 | M29: =SUMIF(Fenster!$D$10:$D$2160,Fassade!F29,Fenster!$J$10:$J$2160) -> 0 | N29: =SUMIF(Fenster!$D$10:$D$2160,Fassade!F29,Fenster!$M$10:$M$2160) -> 0 | O29: =SUMIFS(Fenster!$M$10:$M$2160,Fenster!$D$10:$D$2160,Fassade!F29,Fenster!$L$10:$L$2160,">2,5") -> 0 | P29: =SUMIF(Fenster!$D$10:$D$2160,Fassade!F29,Fenster!$K$10:$K$2160) -> 0 | Q29: =L29-O29 -> 0 | R29: =L29-N29 -> 0 | U29: Bemerkung:
B30: Kellerwand?: | L30: =H30*I30+J30 -> 0 | M30: =SUMIF(Fenster!$D$10:$D$2160,Fassade!F30,Fenster!$J$10:$J$2160) -> 0 | N30: =SUMIF(Fenster!$D$10:$D$2160,Fassade!F30,Fenster!$M$10:$M$2160) -> 0 | O30: =SUMIFS(Fenster!$M$10:$M$2160,Fenster!$D$10:$D$2160,Fassade!F30,Fenster!$L$10:$L$2160,">2,5") -> 0 | P30: =SUMIF(Fenster!$D$10:$D$2160,Fassade!F30,Fenster!$K$10:$K$2160) -> 0 | Q30: =L30-O30 -> 0 | R30: =L30-N30 -> 0
L31: =H31*I31+J31 -> 0 | M31: =SUMIF(Fenster!$D$10:$D$2160,Fassade!F31,Fenster!$J$10:$J$2160) -> 0 | N31: =SUMIF(Fenster!$D$10:$D$2160,Fassade!F31,Fenster!$M$10:$M$2160) -> 0 | O31: =SUMIFS(Fenster!$M$10:$M$2160,Fenster!$D$10:$D$2160,Fassade!F31,Fenster!$L$10:$L$2160,">2,5") -> 0 | P31: =SUMIF(Fenster!$D$10:$D$2160,Fassade!F31,Fenster!$K$10:$K$2160) -> 0 | Q31: =L31-O31 -> 0 | R31: =L31-N31 -> 0
L32: =H32*I32+J32 -> 0 | M32: =SUMIF(Fenster!$D$10:$D$2160,Fassade!F32,Fenster!$J$10:$J$2160) -> 0 | N32: =SUMIF(Fenster!$D$10:$D$2160,Fassade!F32,Fenster!$M$10:$M$2160) -> 0 | O32: =SUMIFS(Fenster!$M$10:$M$2160,Fenster!$D$10:$D$2160,Fassade!F32,Fenster!$L$10:$L$2160,">2,5") -> 0 | P32: =SUMIF(Fenster!$D$10:$D$2160,Fassade!F32,Fenster!$K$10:$K$2160) -> 0 | Q32: =L32-O32 -> 0 | R32: =L32-N32 -> 0
L33: =H33*I33+J33 -> 0 | M33: =SUMIF(Fenster!$D$10:$D$2160,Fassade!F33,Fenster!$J$10:$J$2160) -> 0 | N33: =SUMIF(Fenster!$D$10:$D$2160,Fassade!F33,Fenster!$M$10:$M$2160) -> 0 | O33: =SUMIFS(Fenster!$M$10:$M$2160,Fenster!$D$10:$D$2160,Fassade!F33,Fenster!$L$10:$L$2160,">2,5") -> 0 | P33: =SUMIF(Fenster!$D$10:$D$2160,Fassade!F33,Fenster!$K$10:$K$2160) -> 0 | Q33: =L33-O33 -> 0 | R33: =L33-N33 -> 0
L34: =H34*I34+J34 -> 0 | M34: =SUMIF(Fenster!$D$10:$D$2160,Fassade!F34,Fenster!$J$10:$J$2160) -> 0 | N34: =SUMIF(Fenster!$D$10:$D$2160,Fassade!F34,Fenster!$M$10:$M$2160) -> 0 | O34: =SUMIFS(Fenster!$M$10:$M$2160,Fenster!$D$10:$D$2160,Fassade!F34,Fenster!$L$10:$L$2160,">2,5") -> 0 | P34: =SUMIF(Fenster!$D$10:$D$2160,Fassade!F34,Fenster!$K$10:$K$2160) -> 0 | Q34: =L34-O34 -> 0 | R34: =L34-N34 -> 0
F35: Summe: | L35: =SUM(L25:L34) -> 0 | M35: =SUM(M25:M34) -> 0 | N35: =SUM(N25:N34) -> 0 | O35: =SUM(O25:O34) -> 0 | P35: =SUM(P25:P34) -> 0 | Q35: =SUM(Q25:Q34) -> 0 | R35: =SUM(R25:R34) -> 0
B37: Monolithisches Mauerwerk | D37: #VALUE! | F37: Benennung | G37: Beschreibung | H37: Breite [m] | I37: Höhe [m] | J37: Zusatzfläche (Bsp. Giebel) | K37: Anmerkung Zusatzfläche | L37: Brutto- fläche [m²] | M37: Anzahl Öffnungen | N37: Öffnungs- fläche [m²] | O37: Öffnungs- fläche über 2,5 m² [m²] | P37: Umfang Öffnungen [m] | Q37: Kalkulatorische Fläche [m²] | R37: Nettofläche zu dämmen [m²] | U37: WDVS: | V37: {=_xlfn.XLOOKUP(U37&Allgemein!$C$45,Fassadenpositionen[[#Headers],[WDVS:]]&Fassadenpositionen[Position Fassade],Fassadenpositionen[WDVS:],"",0,1)} -> Nein | W37: {=_xlfn.XLOOKUP(U37&Allgemein!$C$61,Fassadenpositionen[[#Headers],[WDVS:]]&Fassadenpositionen[Position Fassade],Fassadenpositionen[WDVS:],"",0,1)} -> Nein | X37: {=_xlfn.XLOOKUP(U37&Allgemein!$C$77,Fassadenpositionen[[#Headers],[WDVS:]]&Fassadenpositionen[Position Fassade],Fassadenpositionen[WDVS:],"",0,1)} -> Nein
B38: Außenwandtyp_xx | L38: =H38*I38+J38 -> 0 | M38: =SUMIF(Fenster!$D$10:$D$2160,Fassade!F38,Fenster!$J$10:$J$2160) -> 0 | N38: =SUMIF(Fenster!$D$10:$D$2160,Fassade!F38,Fenster!$M$10:$M$2160) -> 0 | O38: =SUMIFS(Fenster!$M$10:$M$2160,Fenster!$D$10:$D$2160,Fassade!F38,Fenster!$L$10:$L$2160,">2,5") -> 0 | P38: =SUMIF(Fenster!$D$10:$D$2160,Fassade!F38,Fenster!$K$10:$K$2160) -> 0 | Q38: =L38-O38 -> 0 | R38: =L38-N38 -> 0 | U38: Zusatz oder Abzugsfläche [m²]: | V38: 0 | W38: 0 | X38: 0
B39: Material Außenwand (1): | L39: =H39*I39+J39 -> 0 | M39: =SUMIF(Fenster!$D$10:$D$2160,Fassade!F39,Fenster!$J$10:$J$2160) -> 0 | N39: =SUMIF(Fenster!$D$10:$D$2160,Fassade!F39,Fenster!$M$10:$M$2160) -> 0 | O39: =SUMIFS(Fenster!$M$10:$M$2160,Fenster!$D$10:$D$2160,Fassade!F39,Fenster!$L$10:$L$2160,">2,5") -> 0 | P39: =SUMIF(Fenster!$D$10:$D$2160,Fassade!F39,Fenster!$K$10:$K$2160) -> 0 | Q39: =L39-O39 -> 0 | R39: =L39-N39 -> 0 | U39: Kalkulatorische Fläche: | V39: =IF(V37="Ja",(Q48+V38)*$V$9,0) -> 0 | W39: =IF(W37="Ja",(Q48+W38)*$V$9,0) -> 0 | X39: =IF(X37="Ja",(Q48+X38)*$V$9,0) -> 0
B40: Stärke Außenwand (1) [cm]: | L40: =H40*I40+J40 -> 0 | M40: =SUMIF(Fenster!$D$10:$D$2160,Fassade!F40,Fenster!$J$10:$J$2160) -> 0 | N40: =SUMIF(Fenster!$D$10:$D$2160,Fassade!F40,Fenster!$M$10:$M$2160) -> 0 | O40: =SUMIFS(Fenster!$M$10:$M$2160,Fenster!$D$10:$D$2160,Fassade!F40,Fenster!$L$10:$L$2160,">2,5") -> 0 | P40: =SUMIF(Fenster!$D$10:$D$2160,Fassade!F40,Fenster!$K$10:$K$2160) -> 0 | Q40: =L40-O40 -> 0 | R40: =L40-N40 -> 0 | U40: Nettofläche zu dämmen: | V40: =IF(V37="Ja",(R48+V38)*$V$9,0) -> 0 | W40: =IF(W37="Ja",(R48+W38)*$V$9,0) -> 0 | X40: =IF(X37="Ja",(R48+X38)*$V$9,0) -> 0
B41: U-Wert [W/(m²K)]: | L41: =H41*I41+J41 -> 0 | M41: =SUMIF(Fenster!$D$10:$D$2160,Fassade!F41,Fenster!$J$10:$J$2160) -> 0 | N41: =SUMIF(Fenster!$D$10:$D$2160,Fassade!F41,Fenster!$M$10:$M$2160) -> 0 | O41: =SUMIFS(Fenster!$M$10:$M$2160,Fenster!$D$10:$D$2160,Fassade!F41,Fenster!$L$10:$L$2160,">2,5") -> 0 | P41: =SUMIF(Fenster!$D$10:$D$2160,Fassade!F41,Fenster!$K$10:$K$2160) -> 0 | Q41: =L41-O41 -> 0 | R41: =L41-N41 -> 0 | U41: Material, Stärke: | V41: =Allgemein!$D$45 -> - | W41: =Allgemein!$D$61 -> - | X41: =Allgemein!$D$77 -> -
B42: Beschreibung Wandtyp: | L42: =H42*I42+J42 -> 0 | M42: =SUMIF(Fenster!$D$10:$D$2160,Fassade!F42,Fenster!$J$10:$J$2160) -> 0 | N42: =SUMIF(Fenster!$D$10:$D$2160,Fassade!F42,Fenster!$M$10:$M$2160) -> 0 | O42: =SUMIFS(Fenster!$M$10:$M$2160,Fenster!$D$10:$D$2160,Fassade!F42,Fenster!$L$10:$L$2160,">2,5") -> 0 | P42: =SUMIF(Fenster!$D$10:$D$2160,Fassade!F42,Fenster!$K$10:$K$2160) -> 0 | Q42: =L42-O42 -> 0 | R42: =L42-N42 -> 0 | U42: Bemerkung:
B43: Kellerwand?: | L43: =H43*I43+J43 -> 0 | M43: =SUMIF(Fenster!$D$10:$D$2160,Fassade!F43,Fenster!$J$10:$J$2160) -> 0 | N43: =SUMIF(Fenster!$D$10:$D$2160,Fassade!F43,Fenster!$M$10:$M$2160) -> 0 | O43: =SUMIFS(Fenster!$M$10:$M$2160,Fenster!$D$10:$D$2160,Fassade!F43,Fenster!$L$10:$L$2160,">2,5") -> 0 | P43: =SUMIF(Fenster!$D$10:$D$2160,Fassade!F43,Fenster!$K$10:$K$2160) -> 0 | Q43: =L43-O43 -> 0 | R43: =L43-N43 -> 0
...

Sheet Fenster
B2: Projektnummer: | C2: =Allgemein!C2 -> 0 | H2: Fenster und Türen | R2: #VALUE!
B3: Anrede: | C3: =Allgemein!C3 -> 0 | J3: Kurzbeschreibung Maßnahmen
B4: Vorname Nachname: | C4: =Allgemein!C4 -> 0 | H4: Umsetzungsvariante: | J4: =Allgemein!C96 -> 0
B5: Straße, Nr. (Objektadresse): | C5: =Allgemein!C5 -> 0 | H5: Zusatzleistung: | J5: =Allgemein!G96 -> 0
B6: PLZ, Ort:: | C6: =Allgemein!C6 -> 0 | H6: Variante 1: | J6: =Allgemein!C46 -> -
B7: Email: | C7: =Allgemein!C7 -> 0 | H7: Variante 2: | J7: =Allgemein!C62 -> -
B8: Telefon: | C8: =Allgemein!C8 -> 0 | H8: Variante 3: | J8: =Allgemein!C78 -> -
B9: Allgemeines zu Fenster und Türen
B10: Bestand | J10: Zusammenfassung Bestand | L10: Umsetzung
B11: Fenstertypen | C11: Verglasung | D11: Material | E11: Baujahr | F11: U-Wert [W/(m²K)] | G11: Rolladen? | H11: Beschreibung | J11: Gesamtfläche Fenster [m²]: | M11: iSFP | N11: Variante 1 | O11: Variante 2 | R11: iSFP | S11: Variante 1 | T11: Variante 2
B12: Fenstertyp 1 | J12: {=SUMPRODUCT(IF(IF($C$25:$C$74<>"",_xlfn.TEXTBEFORE($C$25:$C$74,"_")="Fenster",),$M$25:$M$74,0))} -> 0 | L12: Fensteraustausch: | M12: {=_xlfn.XLOOKUP(L12&Allgemein!C46,Tabelle2527[[#Headers],[Fensteraustausch:]]&Tabelle2527[Position Fenster],Tabelle2527[Fensteraustausch:],"",0,1)} -> Nein | N12: {=_xlfn.XLOOKUP(L12&Allgemein!C62,Tabelle2527[[#Headers],[Fensteraustausch:]]&Tabelle2527[Position Fenster],Tabelle2527[Fensteraustausch:],"",0,1)} -> Nein | O12: {=_xlfn.XLOOKUP(L12&Allgemein!C78,Tabelle2527[[#Headers],[Fensteraustausch:]]&Tabelle2527[Position Fenster],Tabelle2527[Fensteraustausch:],"",0,1)} -> Nein | Q12: Türaustausch: | R12: {=_xlfn.XLOOKUP(Q12&Allgemein!C46,Tabelle2527[[#Headers],[Türaustausch:]]&Tabelle2527[Position Fenster],Tabelle2527[Türaustausch:],"",0,1)} -> Nein | S12: {=_xlfn.XLOOKUP(Q12&Allgemein!C62,Tabelle2527[[#Headers],[Türaustausch:]]&Tabelle2527[Position Fenster],Tabelle2527[Türaustausch:],"",0,1)} -> Nein | T12: {=_xlfn.XLOOKUP(Q12&Allgemein!C78,Tabelle2527[[#Headers],[Türaustausch:]]&Tabelle2527[Position Fenster],Tabelle2527[Türaustausch:],"",0,1)} -> Nein
B13: Fenstertyp 2 | L13: Austauschfläche [m²]: | M13: =SUMIF(R25:R74,"Ja",$O$25:$O$74) -> 0 | N13: =SUMIF(S25:S74,"Ja",$O$25:$O$74) -> 0 | O13: =SUMIF(T25:T74,"Ja",$O$25:$O$74) -> 0 | Q13: Anzahl Austausch: | R13: {=SUMPRODUCT(IF(IF($C$25:$C$74<>"",IF(R25:R74="Ja",_xlfn.TEXTBEFORE($C$25:$C$74,"_")="Tür",)),$J$25:$J$74,0))} -> 0 | S13: {=SUMPRODUCT(IF(IF($C$25:$C$74<>"",IF(S25:S74="Ja",_xlfn.TEXTBEFORE($C$25:$C$74,"_")="Tür",)),$J$25:$J$74,0))} -> 0 | T13: {=SUMPRODUCT(IF(IF($C$25:$C$74<>"",IF(T25:T74="Ja",_xlfn.TEXTBEFORE($C$25:$C$74,"_")="Tür",)),$J$25:$J$74,0))} -> 0
B14: Fenstertyp 3 | J14: Gesamt Anzahl Türen: | L14: Austausch Anzahl: | M14: =IF(M12="Nein",0,SUMIF(R25:R74,"Ja",$J$25:$J$74)) -> 0 | N14: =IF(N12="Nein",0,SUMIF(S25:S74,"Ja",$J$25:$J$74)) -> 0 | O14: =IF(O12="Nein",0,SUMIF(T25:T74,"Ja",$J$25:$J$74)) -> 0 | Q14: Art:
B15: Fenstertyp 4 | J15: {=SUMPRODUCT(IF(IF($C$25:$C$74<>"",_xlfn.TEXTBEFORE($C$25:$C$74,"_")="Tür",),$J$25:$J$74,0))} -> 0 | L15: Art: | Q15: Bemerkung Ausführung:
B16: Fenstertyp 5 | L16: Summe Fensterbreite [m]: | M16: {=SUMPRODUCT(IF(IF($C$25:$C$74<>"",IF(R25:R74="Ja",_xlfn.TEXTBEFORE($C$25:$C$74,"_")="Fenster",)),$H$25:$H$74*$J$25:$J$74,0))} -> 0 | N16: {=SUMPRODUCT(IF(IF($C$25:$C$74<>"",IF(S25:S74="Ja",_xlfn.TEXTBEFORE($C$25:$C$74,"_")="Fenster",)),$H$25:$H$74*$J$25:$J$74,0))} -> 0 | O16: {=SUMPRODUCT(IF(IF($C$25:$C$74<>"",IF(T25:T74="Ja",_xlfn.TEXTBEFORE($C$25:$C$74,"_")="Fenster",)),$H$25:$H$74*$J$25:$J$74,0))} -> 0
B17: Türtypen | L17: Bemerkung Ausführung:
B18: Türtyp 1
B19: Türtyp 2
B20: Türtyp 3
B21: Türtyp_4
B22: vorhandene Fenster und Türen
N23: Wunsch/Anmerkung | R23: iSFP | S23: Variante 1 | T23: Variante 2
B24: Typ | C24: Benennung | D24: Außenwand | E24: Beschreibung Außenwand | F24: Geschoss | G24: Ausrichtung | H24: Breite [m] | I24: Höhe [m] | J24: Anzahl | K24: Umfang [m] | L24: Fläche-E [m²] | M24: Fläche-G [m²] | N24: Austausch gewünscht? | O24: Austauschfläche Fenster [m²] | P24: Rolladen neu? | Q24: Bemerkung | R24: Austausch iSFP? | S24: Austausch V1?2 | T24: Austausch V2?2
E25: =IF(D25="","",_xlfn.XLOOKUP(D25,Fassade!$F$10:$F$515,Fassade!$G$10:$G$515,"",0,1)) | K25: =(2*H25+2*I25)*J25 -> 0 | L25: =H25*I25 -> 0 | M25: =PRODUCT(H25*I25*J25) -> 0 | O25: =IF(B25="",0,IF(AND(N25="Ja",_xlfn.TEXTBEFORE(Tabelle36[[#This Row],[Benennung]],"_")="Fenster"),H25*I25*J25,0)) -> 0 | R25: =IF(AND(_xlfn.TEXTBEFORE(Tabelle36[[#This Row],[Benennung]],"_")="Fenster",$M$12="Nein"),"Nein",IF(AND(_xlfn.TEXTBEFORE(Tabelle36[[#This Row],[Benennung]],"_")="Tür",$R$12="Nein"),"Nein",IF(Tabelle36[[#This Row],[Austausch gewünscht?]]="Ja","Ja",IF(Tabelle36[[#This Row],[Austausch gewünscht?]]="Nein","Nein","")))) -> #N/A | S25: =IF(AND(_xlfn.TEXTBEFORE(Tabelle36[[#This Row],[Benennung]],"_")="Fenster",$N$12="Nein"),"Nein",IF(AND(_xlfn.TEXTBEFORE(Tabelle36[[#This Row],[Benennung]],"_")="Tür",$S$12="Nein"),"Nein",IF(Tabelle36[[#This Row],[Austausch gewünscht?]]="Ja","Ja",IF(Tabelle36[[#This Row],[Austausch gewünscht?]]="Nein","Nein","")))) -> #N/A | T25: =IF(AND(_xlfn.TEXTBEFORE(Tabelle36[[#This Row],[Benennung]],"_")="Fenster",$O$12="Nein"),"Nein",IF(AND(_xlfn.TEXTBEFORE(Tabelle36[[#This Row],[Benennung]],"_")="Tür",$T$12="Nein"),"Nein",IF(Tabelle36[[#This Row],[Austausch gewünscht?]]="Ja","Ja",IF(Tabelle36[[#This Row],[Austausch gewünscht?]]="Nein","Nein","")))) -> #N/A
E26: =IF(D26="","",_xlfn.XLOOKUP(D26,Fassade!$F$10:$F$515,Fassade!$G$10:$G$515,"",0,1)) | K26: =(2*H26+2*I26)*J26 -> 0 | L26: =H26*I26 -> 0 | M26: =PRODUCT(H26*I26*J26) -> 0 | O26: =IF(B26="",0,IF(AND(N26="Ja",_xlfn.TEXTBEFORE(Tabelle36[[#This Row],[Benennung]],"_")="Fenster"),H26*I26*J26,0)) -> 0 | R26: =IF(AND(_xlfn.TEXTBEFORE(Tabelle36[[#This Row],[Benennung]],"_")="Fenster",$M$12="Nein"),"Nein",IF(AND(_xlfn.TEXTBEFORE(Tabelle36[[#This Row],[Benennung]],"_")="Tür",$R$12="Nein"),"Nein",IF(Tabelle36[[#This Row],[Austausch gewünscht?]]="Ja","Ja",IF(Tabelle36[[#This Row],[Austausch gewünscht?]]="Nein","Nein","")))) -> #N/A | S26: =IF(AND(_xlfn.TEXTBEFORE(Tabelle36[[#This Row],[Benennung]],"_")="Fenster",$N$12="Nein"),"Nein",IF(AND(_xlfn.TEXTBEFORE(Tabelle36[[#This Row],[Benennung]],"_")="Tür",$S$12="Nein"),"Nein",IF(Tabelle36[[#This Row],[Austausch gewünscht?]]="Ja","Ja",IF(Tabelle36[[#This Row],[Austausch gewünscht?]]="Nein","Nein","")))) -> #N/A | T26: =IF(AND(_xlfn.TEXTBEFORE(Tabelle36[[#This Row],[Benennung]],"_")="Fenster",$O$12="Nein"),"Nein",IF(AND(_xlfn.TEXTBEFORE(Tabelle36[[#This Row],[Benennung]],"_")="Tür",$T$12="Nein"),"Nein",IF(Tabelle36[[#This Row],[Austausch gewünscht?]]="Ja","Ja",IF(Tabelle36[[#This Row],[Austausch gewünscht?]]="Nein","Nein","")))) -> #N/A
E27: =IF(D27="","",_xlfn.XLOOKUP(D27,Fassade!$F$10:$F$515,Fassade!$G$10:$G$515,"",0,1)) | K27: =(2*H27+2*I27)*J27 -> 0 | L27: =H27*I27 -> 0 | M27: =PRODUCT(H27*I27*J27) -> 0 | O27: =IF(B27="",0,IF(AND(N27="Ja",_xlfn.TEXTBEFORE(Tabelle36[[#This Row],[Benennung]],"_")="Fenster"),H27*I27*J27,0)) -> 0 | R27: =IF(AND(_xlfn.TEXTBEFORE(Tabelle36[[#This Row],[Benennung]],"_")="Fenster",$M$12="Nein"),"Nein",IF(AND(_xlfn.TEXTBEFORE(Tabelle36[[#This Row],[Benennung]],"_")="Tür",$R$12="Nein"),"Nein",IF(Tabelle36[[#This Row],[Austausch gewünscht?]]="Ja","Ja",IF(Tabelle36[[#This Row],[Austausch gewünscht?]]="Nein","Nein","")))) -> #N/A | S27: =IF(AND(_xlfn.TEXTBEFORE(Tabelle36[[#This Row],[Benennung]],"_")="Fenster",$N$12="Nein"),"Nein",IF(AND(_xlfn.TEXTBEFORE(Tabelle36[[#This Row],[Benennung]],"_")="Tür",$S$12="Nein"),"Nein",IF(Tabelle36[[#This Row],[Austausch gewünscht?]]="Ja","Ja",IF(Tabelle36[[#This Row],[Austausch gewünscht?]]="Nein","Nein","")))) -> #N/A | T27: =IF(AND(_xlfn.TEXTBEFORE(Tabelle36[[#This Row],[Benennung]],"_")="Fenster",$O$12="Nein"),"Nein",IF(AND(_xlfn.TEXTBEFORE(Tabelle36[[#This Row],[Benennung]],"_")="Tür",$T$12="Nein"),"Nein",IF(Tabelle36[[#This Row],[Austausch gewünscht?]]="Ja","Ja",IF(Tabelle36[[#This Row],[Austausch gewünscht?]]="Nein","Nein","")))) -> #N/A
E28: =IF(D28="","",_xlfn.XLOOKUP(D28,Fassade!$F$10:$F$515,Fassade!$G$10:$G$515,"",0,1)) | K28: =(2*H28+2*I28)*J28 -> 0 | L28: =H28*I28 -> 0 | M28: =PRODUCT(H28*I28*J28) -> 0 | O28: =IF(B28="",0,IF(AND(N28="Ja",_xlfn.TEXTBEFORE(Tabelle36[[#This Row],[Benennung]],"_")="Fenster"),H28*I28*J28,0)) -> 0 | R28: =IF(AND(_xlfn.TEXTBEFORE(Tabelle36[[#This Row],[Benennung]],"_")="Fenster",$M$12="Nein"),"Nein",IF(AND(_xlfn.TEXTBEFORE(Tabelle36[[#This Row],[Benennung]],"_")="Tür",$R$12="Nein"),"Nein",IF(Tabelle36[[#This Row],[Austausch gewünscht?]]="Ja","Ja",IF(Tabelle36[[#This Row],[Austausch gewünscht?]]="Nein","Nein","")))) -> #N/A | S28: =IF(AND(_xlfn.TEXTBEFORE(Tabelle36[[#This Row],[Benennung]],"_")="Fenster",$N$12="Nein"),"Nein",IF(AND(_xlfn.TEXTBEFORE(Tabelle36[[#This Row],[Benennung]],"_")="Tür",$S$12="Nein"),"Nein",IF(Tabelle36[[#This Row],[Austausch gewünscht?]]="Ja","Ja",IF(Tabelle36[[#This Row],[Austausch gewünscht?]]="Nein","Nein","")))) -> #N/A | T28: =IF(AND(_xlfn.TEXTBEFORE(Tabelle36[[#This Row],[Benennung]],"_")="Fenster",$O$12="Nein"),"Nein",IF(AND(_xlfn.TEXTBEFORE(Tabelle36[[#This Row],[Benennung]],"_")="Tür",$T$12="Nein"),"Nein",IF(Tabelle36[[#This Row],[Austausch gewünscht?]]="Ja","Ja",IF(Tabelle36[[#This Row],[Austausch gewünscht?]]="Nein","Nein","")))) -> #N/A
E29: =IF(D29="","",_xlfn.XLOOKUP(D29,Fassade!$F$10:$F$515,Fassade!$G$10:$G$515,"",0,1)) | K29: =(2*H29+2*I29)*J29 -> 0 | L29: =H29*I29 -> 0 | M29: =PRODUCT(H29*I29*J29) -> 0 | O29: =IF(B29="",0,IF(AND(N29="Ja",_xlfn.TEXTBEFORE(Tabelle36[[#This Row],[Benennung]],"_")="Fenster"),H29*I29*J29,0)) -> 0 | R29: =IF(AND(_xlfn.TEXTBEFORE(Tabelle36[[#This Row],[Benennung]],"_")="Fenster",$M$12="Nein"),"Nein",IF(AND(_xlfn.TEXTBEFORE(Tabelle36[[#This Row],[Benennung]],"_")="Tür",$R$12="Nein"),"Nein",IF(Tabelle36[[#This Row],[Austausch gewünscht?]]="Ja","Ja",IF(Tabelle36[[#This Row],[Austausch gewünscht?]]="Nein","Nein","")))) -> #N/A | S29: =IF(AND(_xlfn.TEXTBEFORE(Tabelle36[[#This Row],[Benennung]],"_")="Fenster",$N$12="Nein"),"Nein",IF(AND(_xlfn.TEXTBEFORE(Tabelle36[[#This Row],[Benennung]],"_")="Tür",$S$12="Nein"),"Nein",IF(Tabelle36[[#This Row],[Austausch gewünscht?]]="Ja","Ja",IF(Tabelle36[[#This Row],[Austausch gewünscht?]]="Nein","Nein","")))) -> #N/A | T29: =IF(AND(_xlfn.TEXTBEFORE(Tabelle36[[#This Row],[Benennung]],"_")="Fenster",$O$12="Nein"),"Nein",IF(AND(_xlfn.TEXTBEFORE(Tabelle36[[#This Row],[Benennung]],"_")="Tür",$T$12="Nein"),"Nein",IF(Tabelle36[[#This Row],[Austausch gewünscht?]]="Ja","Ja",IF(Tabelle36[[#This Row],[Austausch gewünscht?]]="Nein","Nein","")))) -> #N/A
E30: =IF(D30="","",_xlfn.XLOOKUP(D30,Fassade!$F$10:$F$515,Fassade!$G$10:$G$515,"",0,1)) | K30: =(2*H30+2*I30)*J30 -> 0 | L30: =H30*I30 -> 0 | M30: =PRODUCT(H30*I30*J30) -> 0 | O30: =IF(B30="",0,IF(AND(N30="Ja",_xlfn.TEXTBEFORE(Tabelle36[[#This Row],[Benennung]],"_")="Fenster"),H30*I30*J30,0)) -> 0 | R30: =IF(AND(_xlfn.TEXTBEFORE(Tabelle36[[#This Row],[Benennung]],"_")="Fenster",$M$12="Nein"),"Nein",IF(AND(_xlfn.TEXTBEFORE(Tabelle36[[#This Row],[Benennung]],"_")="Tür",$R$12="Nein"),"Nein",IF(Tabelle36[[#This Row],[Austausch gewünscht?]]="Ja","Ja",IF(Tabelle36[[#This Row],[Austausch gewünscht?]]="Nein","Nein","")))) -> #N/A | S30: =IF(AND(_xlfn.TEXTBEFORE(Tabelle36[[#This Row],[Benennung]],"_")="Fenster",$N$12="Nein"),"Nein",IF(AND(_xlfn.TEXTBEFORE(Tabelle36[[#This Row],[Benennung]],"_")="Tür",$S$12="Nein"),"Nein",IF(Tabelle36[[#This Row],[Austausch gewünscht?]]="Ja","Ja",IF(Tabelle36[[#This Row],[Austausch gewünscht?]]="Nein","Nein","")))) -> #N/A | T30: =IF(AND(_xlfn.TEXTBEFORE(Tabelle36[[#This Row],[Benennung]],"_")="Fenster",$O$12="Nein"),"Nein",IF(AND(_xlfn.TEXTBEFORE(Tabelle36[[#This Row],[Benennung]],"_")="Tür",$T$12="Nein"),"Nein",IF(Tabelle36[[#This Row],[Austausch gewünscht?]]="Ja","Ja",IF(Tabelle36[[#This Row],[Austausch gewünscht?]]="Nein","Nein","")))) -> #N/A
E31: =IF(D31="","",_xlfn.XLOOKUP(D31,Fassade!$F$10:$F$515,Fassade!$G$10:$G$515,"",0,1)) | K31: =(2*H31+2*I31)*J31 -> 0 | L31: =H31*I31 -> 0 | M31: =PRODUCT(H31*I31*J31) -> 0 | O31: =IF(B31="",0,IF(AND(N31="Ja",_xlfn.TEXTBEFORE(Tabelle36[[#This Row],[Benennung]],"_")="Fenster"),H31*I31*J31,0)) -> 0 | R31: =IF(AND(_xlfn.TEXTBEFORE(Tabelle36[[#This Row],[Benennung]],"_")="Fenster",$M$12="Nein"),"Nein",IF(AND(_xlfn.TEXTBEFORE(Tabelle36[[#This Row],[Benennung]],"_")="Tür",$R$12="Nein"),"Nein",IF(Tabelle36[[#This Row],[Austausch gewünscht?]]="Ja","Ja",IF(Tabelle36[[#This Row],[Austausch gewünscht?]]="Nein","Nein","")))) -> #N/A | S31: =IF(AND(_xlfn.TEXTBEFORE(Tabelle36[[#This Row],[Benennung]],"_")="Fenster",$N$12="Nein"),"Nein",IF(AND(_xlfn.TEXTBEFORE(Tabelle36[[#This Row],[Benennung]],"_")="Tür",$S$12="Nein"),"Nein",IF(Tabelle36[[#This Row],[Austausch gewünscht?]]="Ja","Ja",IF(Tabelle36[[#This Row],[Austausch gewünscht?]]="Nein","Nein","")))) -> #N/A | T31: =IF(AND(_xlfn.TEXTBEFORE(Tabelle36[[#This Row],[Benennung]],"_")="Fenster",$O$12="Nein"),"Nein",IF(AND(_xlfn.TEXTBEFORE(Tabelle36[[#This Row],[Benennung]],"_")="Tür",$T$12="Nein"),"Nein",IF(Tabelle36[[#This Row],[Austausch gewünscht?]]="Ja","Ja",IF(Tabelle36[[#This Row],[Austausch gewünscht?]]="Nein","Nein","")))) -> #N/A
E32: =IF(D32="","",_xlfn.XLOOKUP(D32,Fassade!$F$10:$F$515,Fassade!$G$10:$G$515,"",0,1)) | K32: =(2*H32+2*I32)*J32 -> 0 | L32: =H32*I32 -> 0 | M32: =PRODUCT(H32*I32*J32) -> 0 | O32: =IF(B32="",0,IF(AND(N32="Ja",_xlfn.TEXTBEFORE(Tabelle36[[#This Row],[Benennung]],"_")="Fenster"),H32*I32*J32,0)) -> 0 | R32: =IF(AND(_xlfn.TEXTBEFORE(Tabelle36[[#This Row],[Benennung]],"_")="Fenster",$M$12="Nein"),"Nein",IF(AND(_xlfn.TEXTBEFORE(Tabelle36[[#This Row],[Benennung]],"_")="Tür",$R$12="Nein"),"Nein",IF(Tabelle36[[#This Row],[Austausch gewünscht?]]="Ja","Ja",IF(Tabelle36[[#This Row],[Austausch gewünscht?]]="Nein","Nein","")))) -> #N/A | S32: =IF(AND(_xlfn.TEXTBEFORE(Tabelle36[[#This Row],[Benennung]],"_")="Fenster",$N$12="Nein"),"Nein",IF(AND(_xlfn.TEXTBEFORE(Tabelle36[[#This Row],[Benennung]],"_")="Tür",$S$12="Nein"),"Nein",IF(Tabelle36[[#This Row],[Austausch gewünscht?]]="Ja","Ja",IF(Tabelle36[[#This Row],[Austausch gewünscht?]]="Nein","Nein","")))) -> #N/A | T32: =IF(AND(_xlfn.TEXTBEFORE(Tabelle36[[#This Row],[Benennung]],"_")="Fenster",$O$12="Nein"),"Nein",IF(AND(_xlfn.TEXTBEFORE(Tabelle36[[#This Row],[Benennung]],"_")="Tür",$T$12="Nein"),"Nein",IF(Tabelle36[[#This Row],[Austausch gewünscht?]]="Ja","Ja",IF(Tabelle36[[#This Row],[Austausch gewünscht?]]="Nein","Nein","")))) -> #N/A
E33: =IF(D33="","",_xlfn.XLOOKUP(D33,Fassade!$F$10:$F$515,Fassade!$G$10:$G$515,"",0,1)) | K33: =(2*H33+2*I33)*J33 -> 0 | L33: =H33*I33 -> 0 | M33: =PRODUCT(H33*I33*J33) -> 0 | O33: =IF(B33="",0,IF(AND(N33="Ja",_xlfn.TEXTBEFORE(Tabelle36[[#This Row],[Benennung]],"_")="Fenster"),H33*I33*J33,0)) -> 0 | R33: =IF(AND(_xlfn.TEXTBEFORE(Tabelle36[[#This Row],[Benennung]],"_")="Fenster",$M$12="Nein"),"Nein",IF(AND(_xlfn.TEXTBEFORE(Tabelle36[[#This Row],[Benennung]],"_")="Tür",$R$12="Nein"),"Nein",IF(Tabelle36[[#This Row],[Austausch gewünscht?]]="Ja","Ja",IF(Tabelle36[[#This Row],[Austausch gewünscht?]]="Nein","Nein","")))) -> #N/A | S33: =IF(AND(_xlfn.TEXTBEFORE(Tabelle36[[#This Row],[Benennung]],"_")="Fenster",$N$12="Nein"),"Nein",IF(AND(_xlfn.TEXTBEFORE(Tabelle36[[#This Row],[Benennung]],"_")="Tür",$S$12="Nein"),"Nein",IF(Tabelle36[[#This Row],[Austausch gewünscht?]]="Ja","Ja",IF(Tabelle36[[#This Row],[Austausch gewünscht?]]="Nein","Nein","")))) -> #N/A | T33: =IF(AND(_xlfn.TEXTBEFORE(Tabelle36[[#This Row],[Benennung]],"_")="Fenster",$O$12="Nein"),"Nein",IF(AND(_xlfn.TEXTBEFORE(Tabelle36[[#This Row],[Benennung]],"_")="Tür",$T$12="Nein"),"Nein",IF(Tabelle36[[#This Row],[Austausch gewünscht?]]="Ja","Ja",IF(Tabelle36[[#This Row],[Austausch gewünscht?]]="Nein","Nein","")))) -> #N/A
